# Captain's Log - 2025-07-25

## Import Issue Resolution - Untracked Test Classes

### Issue Discovery
Colleague reported an import error when downloading the latest version of plotbot from GitHub. Investigation revealed a critical initialization problem in `plotbot/__init__.py`.

### Root Cause Analysis

**The Problem:**
```python
# PROBLEMATIC IMPORTS in __init__.py:
from .data_classes.custom_classes.test_version_1_5_multi import test_version_1_5_multi, test_version_1_5_multi_class
from .data_classes.custom_classes.test_version_1_5_single import test_version_1_5_single, test_version_1_5_single_class
```

**Why This Failed:**
- These test class files existed locally (untracked in git)
- Files were auto-generated during CDF development but never committed
- When colleague downloaded repo, files were missing → `ImportError`

**Git Status Showed:**
```
Untracked files:
	plotbot/data_classes/custom_classes/test_version_1_5_multi.py
	plotbot/data_classes/custom_classes/test_version_1_5_multi.pyi  
	plotbot/data_classes/custom_classes/test_version_1_5_single.py
	plotbot/data_classes/custom_classes/test_version_1_5_single.pyi
```

### Resolution Applied

**Step 1: Remove Problematic Imports**
- Edited `plotbot/__init__.py` to remove imports for untracked test classes
- Cleaned up duplicate entries in `__all__` list
- Removed duplicate custom class import sections

**Step 2: Delete Untracked Files**
- Removed `test_version_1_5_multi.py` and `.pyi` files
- Removed `test_version_1_5_single.py` and `.pyi` files
- These were test artifacts, not production code

**Step 3: Verification**
```bash
conda run -n plotbot_env python -c "import plotbot; print('✅ Plotbot imported successfully!')"
```
Result: ✅ **Import successful - issue resolved**

### Secondary Issue: Environment Confusion

**Initial Test Error:**
```bash
python -c "import plotbot"
# ❌ ModuleNotFoundError: No module named 'cdflib'
```

**Explanation:**
- System python lacks plotbot dependencies
- Conda environment (`plotbot_env`) has all required packages
- `cdflib` is properly included in both `requirements.txt` and `environment.yml`
- No code issue - just testing in wrong environment

**Lesson Learned:**
Always test with proper environment when validating plotbot functionality.

### Files Modified

**`plotbot/__init__.py`:**
- Removed untracked test class imports  
- Cleaned duplicate `__all__` entries
- Maintained all legitimate custom CDF classes

**Files Deleted:**
- `plotbot/data_classes/custom_classes/test_version_1_5_multi.py`
- `plotbot/data_classes/custom_classes/test_version_1_5_multi.pyi`
- `plotbot/data_classes/custom_classes/test_version_1_5_single.py`
- `plotbot/data_classes/custom_classes/test_version_1_5_single.pyi`

### Impact & Resolution

**Before Fix:**
- Fresh plotbot downloads failed with `ImportError`
- Untracked development artifacts breaking production imports
- Duplicate and inconsistent `__init__.py` configuration

**After Fix:**
- Clean plotbot import for all users
- Proper separation of development/test artifacts from production code
- Consistent auto-registration of legitimate custom CDF classes

**Status:** ✅ **Issue resolved - plotbot imports cleanly for all users**

**Next Steps:**
- Commit and push fix to ensure all users get working version
- Consider improving auto-generation to avoid future untracked import issues 